Workbook

Sheet HUD
A1: ⚔️ F I G H T E R ' S O S
A2: FlyeFit Macken Street | Combat Performance System
A4: SELECT YOUR DAY | B4: Day 1 | D4: PHASE | E4: ="Phase "&Settings!B3 | F4: HIP SCORE (1-5) | G4: 3 | H4: =IF(G4<=2,"🔴 HIGH ALERT",IF(G4=3,"🟡 MODERATE","🟢 GOOD"))
A5: =IF(OR(B4="Day 2",B4="Day 4"),"🥊 FIGHT GYM DAY — Log your session in the Notes section below","")
A7: 🔥 MOBILITY & INJURY PREP
A8: Movement | B8: ✓ Done | C8: Duration | D8: Coach Cue
A9: =IF(H4<=2,IF(IFERROR(INDEX(Playbook!G:G,MATCH("P"&Settings!B3&"-D"&MID(B4,5,1)&"-MOB-1-HA",Playbook!A:A,0)),"")<>"","🔴 "&IFERROR(INDEX(Playbook!G:G,MATCH("P"&Settings!B3&"-D"&MID(B4,5,1)&"-MOB-1-HA",Playbook!A:A,0)),""),IFERROR(INDEX(Playbook!G:G,MATCH("P"&Settings!B3&"-D"&MID(B4,5,1)&"-MOB-1-STD",Playbook!A:A,0)),"")),IFERROR(INDEX(Playbook!G:G,MATCH("P"&Settings!B3&"-D"&MID(B4,5,1)&"-MOB-1-STD",Playbook!A:A,0)),"")) | B9: FALSE | C9: =IFERROR(INDEX(Playbook!I:I,MATCH("P"&Settings!B3&"-D"&MID(B4,5,1)&"-MOB-1-STD",Playbook!A:A,0)),"") | D9: =IF(H4<=2,IF(IFERROR(INDEX(Playbook!O:O,MATCH("P"&Settings!B3&"-D"&MID(B4,5,1)&"-MOB-1-HA",Playbook!A:A,0)),"")<>"","🔴 "&IFERROR(INDEX(Playbook!O:O,MATCH("P"&Settings!B3&"-D"&MID(B4,5,1)&"-MOB-1-HA",Playbook!A:A,0)),""),IFERROR(INDEX(Playbook!O:O,MATCH("P"&Settings!B3&"-D"&MID(B4,5,1)&"-MOB-1-STD",Playbook!A:A,0)),"")),IFERROR(INDEX(Playbook!O:O,MATCH("P"&Settings!B3&"-D"&MID(B4,5,1)&"-MOB-1-STD",Playbook!A:A,0)),""))
A10: =IF(H4<=2,IF(IFERROR(INDEX(Playbook!G:G,MATCH("P"&Settings!B3&"-D"&MID(B4,5,1)&"-MOB-2-HA",Playbook!A:A,0)),"")<>"","🔴 "&IFERROR(INDEX(Playbook!G:G,MATCH("P"&Settings!B3&"-D"&MID(B4,5,1)&"-MOB-2-HA",Playbook!A:A,0)),""),IFERROR(INDEX(Playbook!G:G,MATCH("P"&Settings!B3&"-D"&MID(B4,5,1)&"-MOB-2-STD",Playbook!A:A,0)),"")),IFERROR(INDEX(Playbook!G:G,MATCH("P"&Settings!B3&"-D"&MID(B4,5,1)&"-MOB-2-STD",Playbook!A:A,0)),"")) | B10: FALSE | C10: =IFERROR(INDEX(Playbook!I:I,MATCH("P"&Settings!B3&"-D"&MID(B4,5,1)&"-MOB-2-STD",Playbook!A:A,0)),"") | D10: =IF(H4<=2,IF(IFERROR(INDEX(Playbook!O:O,MATCH("P"&Settings!B3&"-D"&MID(B4,5,1)&"-MOB-2-HA",Playbook!A:A,0)),"")<>"","🔴 "&IFERROR(INDEX(Playbook!O:O,MATCH("P"&Settings!B3&"-D"&MID(B4,5,1)&"-MOB-2-HA",Playbook!A:A,0)),""),IFERROR(INDEX(Playbook!O:O,MATCH("P"&Settings!B3&"-D"&MID(B4,5,1)&"-MOB-2-STD",Playbook!A:A,0)),"")),IFERROR(INDEX(Playbook!O:O,MATCH("P"&Settings!B3&"-D"&MID(B4,5,1)&"-MOB-2-STD",Playbook!A:A,0)),""))
A11: =IF(H4<=2,IF(IFERROR(INDEX(Playbook!G:G,MATCH("P"&Settings!B3&"-D"&MID(B4,5,1)&"-MOB-3-HA",Playbook!A:A,0)),"")<>"","🔴 "&IFERROR(INDEX(Playbook!G:G,MATCH("P"&Settings!B3&"-D"&MID(B4,5,1)&"-MOB-3-HA",Playbook!A:A,0)),""),IFERROR(INDEX(Playbook!G:G,MATCH("P"&Settings!B3&"-D"&MID(B4,5,1)&"-MOB-3-STD",Playbook!A:A,0)),"")),IFERROR(INDEX(Playbook!G:G,MATCH("P"&Settings!B3&"-D"&MID(B4,5,1)&"-MOB-3-STD",Playbook!A:A,0)),"")) | B11: FALSE | C11: =IFERROR(INDEX(Playbook!I:I,MATCH("P"&Settings!B3&"-D"&MID(B4,5,1)&"-MOB-3-STD",Playbook!A:A,0)),"") | D11: =IF(H4<=2,IF(IFERROR(INDEX(Playbook!O:O,MATCH("P"&Settings!B3&"-D"&MID(B4,5,1)&"-MOB-3-HA",Playbook!A:A,0)),"")<>"","🔴 "&IFERROR(INDEX(Playbook!O:O,MATCH("P"&Settings!B3&"-D"&MID(B4,5,1)&"-MOB-3-HA",Playbook!A:A,0)),""),IFERROR(INDEX(Playbook!O:O,MATCH("P"&Settings!B3&"-D"&MID(B4,5,1)&"-MOB-3-STD",Playbook!A:A,0)),"")),IFERROR(INDEX(Playbook!O:O,MATCH("P"&Settings!B3&"-D"&MID(B4,5,1)&"-MOB-3-STD",Playbook!A:A,0)),""))
A12: =IF(H4<=2,IF(IFERROR(INDEX(Playbook!G:G,MATCH("P"&Settings!B3&"-D"&MID(B4,5,1)&"-MOB-4-HA",Playbook!A:A,0)),"")<>"","🔴 "&IFERROR(INDEX(Playbook!G:G,MATCH("P"&Settings!B3&"-D"&MID(B4,5,1)&"-MOB-4-HA",Playbook!A:A,0)),""),IFERROR(INDEX(Playbook!G:G,MATCH("P"&Settings!B3&"-D"&MID(B4,5,1)&"-MOB-4-STD",Playbook!A:A,0)),"")),IFERROR(INDEX(Playbook!G:G,MATCH("P"&Settings!B3&"-D"&MID(B4,5,1)&"-MOB-4-STD",Playbook!A:A,0)),"")) | B12: FALSE | C12: =IFERROR(INDEX(Playbook!I:I,MATCH("P"&Settings!B3&"-D"&MID(B4,5,1)&"-MOB-4-STD",Playbook!A:A,0)),"") | D12: =IF(H4<=2,IF(IFERROR(INDEX(Playbook!O:O,MATCH("P"&Settings!B3&"-D"&MID(B4,5,1)&"-MOB-4-HA",Playbook!A:A,0)),"")<>"","🔴 "&IFERROR(INDEX(Playbook!O:O,MATCH("P"&Settings!B3&"-D"&MID(B4,5,1)&"-MOB-4-HA",Playbook!A:A,0)),""),IFERROR(INDEX(Playbook!O:O,MATCH("P"&Settings!B3&"-D"&MID(B4,5,1)&"-MOB-4-STD",Playbook!A:A,0)),"")),IFERROR(INDEX(Playbook!O:O,MATCH("P"&Settings!B3&"-D"&MID(B4,5,1)&"-MOB-4-STD",Playbook!A:A,0)),""))
A13: =IF(H4<=2,IF(IFERROR(INDEX(Playbook!G:G,MATCH("P"&Settings!B3&"-D"&MID(B4,5,1)&"-MOB-5-HA",Playbook!A:A,0)),"")<>"","🔴 "&IFERROR(INDEX(Playbook!G:G,MATCH("P"&Settings!B3&"-D"&MID(B4,5,1)&"-MOB-5-HA",Playbook!A:A,0)),""),IFERROR(INDEX(Playbook!G:G,MATCH("P"&Settings!B3&"-D"&MID(B4,5,1)&"-MOB-5-STD",Playbook!A:A,0)),"")),IFERROR(INDEX(Playbook!G:G,MATCH("P"&Settings!B3&"-D"&MID(B4,5,1)&"-MOB-5-STD",Playbook!A:A,0)),"")) | B13: FALSE | C13: =IFERROR(INDEX(Playbook!I:I,MATCH("P"&Settings!B3&"-D"&MID(B4,5,1)&"-MOB-5-STD",Playbook!A:A,0)),"") | D13: =IF(H4<=2,IF(IFERROR(INDEX(Playbook!O:O,MATCH("P"&Settings!B3&"-D"&MID(B4,5,1)&"-MOB-5-HA",Playbook!A:A,0)),"")<>"","🔴 "&IFERROR(INDEX(Playbook!O:O,MATCH("P"&Settings!B3&"-D"&MID(B4,5,1)&"-MOB-5-HA",Playbook!A:A,0)),""),IFERROR(INDEX(Playbook!O:O,MATCH("P"&Settings!B3&"-D"&MID(B4,5,1)&"-MOB-5-STD",Playbook!A:A,0)),"")),IFERROR(INDEX(Playbook!O:O,MATCH("P"&Settings!B3&"-D"&MID(B4,5,1)&"-MOB-5-STD",Playbook!A:A,0)),""))
A15: 💪 STRENGTH + PAP SUPERSETS
A16: Exercise | B16: S1 kg | C16: S1 reps | D16: S2 kg | E16: S2 reps | F16: S3 kg | G16: S3 reps | H16: S4 kg | I16: S4 reps
A17: =IF(IFERROR(INDEX(Playbook!G:G,MATCH("P"&Settings!B3&"-D"&MID(B4,5,1)&"-STR-1",Playbook!A:A,0)),"")="","","[A] "&IFERROR(INDEX(Playbook!G:G,MATCH("P"&Settings!B3&"-D"&MID(B4,5,1)&"-STR-1",Playbook!A:A,0)),"")) | B17: =IFERROR("Target: "&INDEX(Playbook!I:I,MATCH("P"&Settings!B3&"-D"&MID(B4,5,1)&"-STR-1",Playbook!A:A,0))&" | "&INDEX(Playbook!J:J,MATCH("P"&Settings!B3&"-D"&MID(B4,5,1)&"-STR-1",Playbook!A:A,0)),"") | I17: =IFERROR("💡 "&INDEX(Playbook!O:O,MATCH("P"&Settings!B3&"-D"&MID(B4,5,1)&"-STR-1",Playbook!A:A,0)),"")
A18: Set 1
A19: Set 2
A20: Set 3
A21: Set 4
A22: =IFERROR("⚡ PAP: "&INDEX(Playbook!K:K,MATCH("P"&Settings!B3&"-D"&MID(B4,5,1)&"-STR-1",Playbook!A:A,0))&" ("&INDEX(Playbook!L:L,MATCH("P"&Settings!B3&"-D"&MID(B4,5,1)&"-STR-1",Playbook!A:A,0))&"×"&INDEX(Playbook!M:M,MATCH("P"&Settings!B3&"-D"&MID(B4,5,1)&"-STR-1",Playbook!A:A,0))&")","—") | B22: FALSE | C22: ✓ PAP Done
A23: =IF(IFERROR(INDEX(Playbook!G:G,MATCH("P"&Settings!B3&"-D"&MID(B4,5,1)&"-STR-2",Playbook!A:A,0)),"")="","","[B] "&IFERROR(INDEX(Playbook!G:G,MATCH("P"&Settings!B3&"-D"&MID(B4,5,1)&"-STR-2",Playbook!A:A,0)),"")) | B23: =IFERROR("Target: "&INDEX(Playbook!I:I,MATCH("P"&Settings!B3&"-D"&MID(B4,5,1)&"-STR-2",Playbook!A:A,0))&" | "&INDEX(Playbook!J:J,MATCH("P"&Settings!B3&"-D"&MID(B4,5,1)&"-STR-2",Playbook!A:A,0)),"") | I23: =IFERROR("💡 "&INDEX(Playbook!O:O,MATCH("P"&Settings!B3&"-D"&MID(B4,5,1)&"-STR-2",Playbook!A:A,0)),"")
A24: Set 1
A25: Set 2
A26: Set 3
A27: Set 4
A28: =IFERROR("⚡ PAP: "&INDEX(Playbook!K:K,MATCH("P"&Settings!B3&"-D"&MID(B4,5,1)&"-STR-2",Playbook!A:A,0))&" ("&INDEX(Playbook!L:L,MATCH("P"&Settings!B3&"-D"&MID(B4,5,1)&"-STR-2",Playbook!A:A,0))&"×"&INDEX(Playbook!M:M,MATCH("P"&Settings!B3&"-D"&MID(B4,5,1)&"-STR-2",Playbook!A:A,0))&")","—") | B28: FALSE | C28: ✓ PAP Done
A29: =IF(IFERROR(INDEX(Playbook!G:G,MATCH("P"&Settings!B3&"-D"&MID(B4,5,1)&"-STR-3",Playbook!A:A,0)),"")="","","[C] "&IFERROR(INDEX(Playbook!G:G,MATCH("P"&Settings!B3&"-D"&MID(B4,5,1)&"-STR-3",Playbook!A:A,0)),"")) | B29: =IFERROR("Target: "&INDEX(Playbook!I:I,MATCH("P"&Settings!B3&"-D"&MID(B4,5,1)&"-STR-3",Playbook!A:A,0))&" | "&INDEX(Playbook!J:J,MATCH("P"&Settings!B3&"-D"&MID(B4,5,1)&"-STR-3",Playbook!A:A,0)),"") | I29: =IFERROR("💡 "&INDEX(Playbook!O:O,MATCH("P"&Settings!B3&"-D"&MID(B4,5,1)&"-STR-3",Playbook!A:A,0)),"")
A30: Set 1
A31: Set 2
A32: Set 3
A33: Set 4
A34: =IFERROR("⚡ PAP: "&INDEX(Playbook!K:K,MATCH("P"&Settings!B3&"-D"&MID(B4,5,1)&"-STR-3",Playbook!A:A,0))&" ("&INDEX(Playbook!L:L,MATCH("P"&Settings!B3&"-D"&MID(B4,5,1)&"-STR-3",Playbook!A:A,0))&"×"&INDEX(Playbook!M:M,MATCH("P"&Settings!B3&"-D"&MID(B4,5,1)&"-STR-3",Playbook!A:A,0))&")","—") | B34: FALSE | C34: ✓ PAP Done
A35: =IF(IFERROR(INDEX(Playbook!G:G,MATCH("P"&Settings!B3&"-D"&MID(B4,5,1)&"-STR-4",Playbook!A:A,0)),"")="","","[D] "&IFERROR(INDEX(Playbook!G:G,MATCH("P"&Settings!B3&"-D"&MID(B4,5,1)&"-STR-4",Playbook!A:A,0)),"")) | B35: =IFERROR("Target: "&INDEX(Playbook!I:I,MATCH("P"&Settings!B3&"-D"&MID(B4,5,1)&"-STR-4",Playbook!A:A,0))&" | "&INDEX(Playbook!J:J,MATCH("P"&Settings!B3&"-D"&MID(B4,5,1)&"-STR-4",Playbook!A:A,0)),"") | I35: =IFERROR("💡 "&INDEX(Playbook!O:O,MATCH("P"&Settings!B3&"-D"&MID(B4,5,1)&"-STR-4",Playbook!A:A,0)),"")
A36: Set 1
A37: Set 2
A38: Set 3
A39: Set 4
A40: =IFERROR("⚡ PAP: "&INDEX(Playbook!K:K,MATCH("P"&Settings!B3&"-D"&MID(B4,5,1)&"-STR-4",Playbook!A:A,0))&" ("&INDEX(Playbook!L:L,MATCH("P"&Settings!B3&"-D"&MID(B4,5,1)&"-STR-4",Playbook!A:A,0))&"×"&INDEX(Playbook!M:M,MATCH("P"&Settings!B3&"-D"&MID(B4,5,1)&"-STR-4",Playbook!A:A,0))&")","—") | B40: FALSE | C40: ✓ PAP Done
A42: 🥊 VARGA BAG WORK
A43: Target Rounds | B43: =IFERROR(INDEX(Playbook!I:I,MATCH("P"&Settings!B3&"-D"&MID(B4,5,1)&"-BAG-1",Playbook!A:A,0)),"—") | F43: ROUNDS DONE:
A44: Combo Focus | B44: =IFERROR(INDEX(Playbook!N:N,MATCH("P"&Settings!B3&"-D"&MID(B4,5,1)&"-BAG-1",Playbook!A:A,0)),"—")
...

Sheet Settings
A1: ⚙️ FIGHTER'S OS — SETTINGS
A3: CURRENT PHASE | B3: 1 | C3: ← Change to 2 or 3 when unlocked
A4: SESSIONS PER PHASE (threshold) | B4: 12 | C4: Phase 2 unlocks after 12 completed gym sessions
A6: PHASE 1 GYM SESSIONS LOGGED | B6: =COUNTIFS(FightLog!C:C,1,FightLog!B:B,"<>2",FightLog!B:B,"<>4") | C6: Auto-calculated
A7: PHASE 2 GYM SESSIONS LOGGED | B7: =COUNTIFS(FightLog!C:C,2,FightLog!B:B,"<>2",FightLog!B:B,"<>4") | C7: Auto-calculated
A8: PHASE 3 GYM SESSIONS LOGGED | B8: =COUNTIFS(FightLog!C:C,3,FightLog!B:B,"<>2",FightLog!B:B,"<>4") | C8: Auto-calculated
A10: PHASE UNLOCK STATUS | B10: =IF(B6>=B4,"PHASE "&(B3+1)&" UNLOCKED — Update phase above!","Sessions until Phase "&(B3+1)&": "&(B4-B6)) | C10: Auto-updates
A12: ATHLETE | B12: Fighter's OS User | C12: Edit your name
A13: BRANCH | B13: FlyeFit Macken St.

Sheet Playbook
A1: Key | B1: Phase | C1: Day | D1: Block | E1: Slot | F1: Variant | G1: Exercise | H1: Sets | I1: Target_Reps | J1: Load_Note | K1: PAP_Exercise | L1: PAP_Sets | M1: PAP_Reps | N1: Combo_Focus | O1: Cue
A2: P1-D1-MOB-1-STD | B2: 1 | C2: 1 | D2: MOBILITY | E2: 1 | F2: STANDARD | G2: 90/90 Hip Internal/External Rotation | I2: 2x60s each side | J2: RIGHT side priority | O2: Breathe into the position, find end range
A3: P1-D1-MOB-2-STD | B3: 1 | C3: 1 | D3: MOBILITY | E3: 2 | F3: STANDARD | G3: Supine Figure-4 Piriformis | I3: 2x45s each side | J3: Feel the outer hip | O3: Cross ankle over knee, flex foot, gentle pressure
A4: P1-D1-MOB-3-STD | B4: 1 | C4: 1 | D4: MOBILITY | E4: 3 | F4: STANDARD | G4: Half-Kneeling Hip Flexor + PPT | I4: 2x45s each side | J4: RIGHT side priority | O4: Squeeze glute, tuck pelvis — actively stretch psoas
A5: P1-D1-MOB-1-HA | B5: 1 | C5: 1 | D5: MOBILITY | E5: 1 | F5: HIGH_ALERT | G5: Supine Knee Circles (Easy) | I5: 2x10 each direction | J5: Gentle joint warm-up | O5: Slow easy circles to warm the joint only
A6: P1-D1-MOB-2-HA | B6: 1 | C6: 1 | D6: MOBILITY | E6: 2 | F6: HIGH_ALERT | G6: Lying Windshield Wiper | I6: 2x60s | J6: Both legs slow | O6: Feet flat, let knees fall side to side
A7: P1-D1-MOB-3-HA | B7: 1 | C7: 1 | D7: MOBILITY | E7: 3 | F7: HIGH_ALERT | G7: Adductor Longus Pin & Stretch | I7: 2x60s each side | J7: Find the tightest point | O7: Thumb pressure into inner thigh while stretching
A8: P1-D1-MOB-4-HA | B8: 1 | C8: 1 | D8: MOBILITY | E8: 4 | F8: HIGH_ALERT | G8: Supine Band Psoas Floss | I8: 2x45s each side | J8: Gentle traction only | O8: Band around proximal thigh, pull knee to chest gently
A9: P1-D1-MOB-5-HA | B9: 1 | C9: 1 | D9: MOBILITY | E9: 5 | F9: HIGH_ALERT | G9: Hip Joint Distraction (Band) | I9: 2x60s each side | J9: RIGHT side first | O9: Band at groin crease, step away for traction
A10: P1-D1-STR-1 | B10: 1 | C10: 1 | D10: STRENGTH | E10: 1 | F10: STANDARD | G10: Barbell Back Squat | H10: 4 | I10: 4-5 reps | J10: 80% 1RM | K10: Box Jump | L10: 4 | M10: 3 | O10: Controlled 3s descent, drive through heels, full depth
A11: P1-D1-STR-2 | B11: 1 | C11: 1 | D11: STRENGTH | E11: 2 | F11: STANDARD | G11: Romanian Deadlift | H11: 3 | I11: 8 reps | J11: Moderate — feel the hamstring | K11: Broad Jump | L11: 3 | M11: 3 | O11: Neutral spine, hip hinge, stretch at bottom
A12: P1-D1-STR-3 | B12: 1 | C12: 1 | D12: STRENGTH | E12: 3 | F12: STANDARD | G12: Barbell Hip Thrust | H12: 3 | I12: 10 reps | J12: Full glute squeeze 2s hold
A13: P1-D1-BAG-1 | B13: 1 | C13: 1 | D13: BAG | E13: 1 | F13: STANDARD | G13: Bag Work — Jab-Cross Foundation | H13: 6 | I13: 3 min rounds | J13: 60s rest between rounds | N13: R1: Technical Jab-Cross | R2: Jab-Cross-Hook | R3: Double Jab-Cross | R4: + Step Out | R5: Speed Round | R6: Power Round | O13: Stay loose. Snap the jab, rotate the hip into the cross.
A14: P1-D1-CLR-1 | B14: 1 | C14: 1 | D14: COOLDOWN | E14: 1 | F14: STANDARD | G14: Pigeon Pose (Deep) | H14: 3 | I14: 90s each side | J14: RIGHT hip: 3 sets. LEFT: 2 sets | O14: Breathe deep, melt into the floor — this is your most important stretch
A15: P1-D1-CLR-2 | B15: 1 | C15: 1 | D15: COOLDOWN | E15: 2 | F15: STANDARD | G15: Couch Stretch (Psoas/Quad) | H15: 2 | I15: 60s each side | J15: RIGHT side priority | O15: Posterior pelvic tilt throughout — actively stretch the psoas
A16: P1-D1-CLR-3 | B16: 1 | C16: 1 | D16: COOLDOWN | E16: 3 | F16: STANDARD | G16: Butterfly Adductor Stretch | H16: 2 | I16: 60s | J16: Lean forward — feel groin
A17: P1-D1-CLR-4 | B17: 1 | C17: 1 | D17: COOLDOWN | E17: 4 | F17: STANDARD | G17: QL Side Bend (Standing) | H17: 2 | I17: 45s each side | J17: Feel the lateral chain
A18: P1-D3-MOB-1-STD | B18: 1 | C18: 3 | D18: MOBILITY | E18: 1 | F18: STANDARD | G18: Thoracic Rotation with Band | H18: 2 | I18: 10 each side | J18: Full rotation — chin over shoulder | O18: Anchor band, rotate fully, hold 1s at end range
A19: P1-D3-MOB-2-STD | B19: 1 | C19: 3 | D19: MOBILITY | E19: 2 | F19: STANDARD | G19: World's Greatest Stretch | H19: 1 | I19: 5 each side | J19: Slow and controlled | O19: Lunge + elbow to floor + thoracic rotation in one fluid move
A20: P1-D3-MOB-3-STD | B20: 1 | C20: 3 | D20: MOBILITY | E20: 3 | F20: STANDARD | G20: Active Hip Flexor Reach | H20: 2 | I20: 45s each side | J20: Stretch hip flexor while reaching overhead | O20: Half-kneeling, reach opposite arm overhead and laterally
A21: P1-D3-STR-1 | B21: 1 | C21: 3 | D21: STRENGTH | E21: 1 | F21: STANDARD | G21: Incline Barbell Press | H21: 4 | I21: 5 reps | J21: 75% 1RM — explosive intent | K21: Explosive Push-up | L21: 4 | M21: 5 | O21: Controlled down, explosive up — this is PAP prep
A22: P1-D3-STR-2 | B22: 1 | C22: 3 | D22: STRENGTH | E22: 2 | F22: STANDARD | G22: Weighted Dip | H22: 3 | I22: 6 reps | J22: +15kg Phase 1 | K22: Clap Push-up | L22: 3 | M22: 5 | O22: Full ROM — chest to bar depth, explosive press
A23: P1-D3-STR-3 | B23: 1 | C23: 3 | D23: STRENGTH | E23: 3 | F23: STANDARD | G23: Landmine Press (Rotational) | H23: 3 | I23: 8 reps each side | J23: Feel the rotation — punch pattern
A24: P1-D3-BAG-1 | B24: 1 | C24: 3 | D24: BAG | E24: 1 | F24: STANDARD | G24: Bag Work — Cross-Hook-Cross Power | H24: 6 | I24: 3 min rounds | J24: 60s rest between rounds | N24: R1-2: Technical 2-3-2 | R3-4: Combo with footwork | R5: Defence + Counter | R6: All-out power round | O24: RIGHT hand power focus every session — rotate the hip INTO the cross
A25: P1-D3-CLR-1 | B25: 1 | C25: 3 | D25: COOLDOWN | E25: 1 | F25: STANDARD | G25: Doorway Chest Stretch | H25: 2 | I25: 60s | J25: Multiple angles — high/mid/low | O25: Find the tightest angle and stay there
A26: P1-D3-CLR-2 | B26: 1 | C26: 3 | D26: COOLDOWN | E26: 2 | F26: STANDARD | G26: Shoulder Cross-Body Rear Delt | H26: 2 | I26: 45s each | J26: Feel rear delt/capsule | O26: Arm across chest, opposite hand pulls at elbow
A27: P1-D3-CLR-3 | B27: 1 | C27: 3 | D27: COOLDOWN | E27: 3 | F27: STANDARD | G27: Thread-the-Needle T-Spine | H27: 2 | I27: 45s each side | J27: Full thoracic rotation
A28: P1-D3-CLR-4 | B28: 1 | C28: 3 | D28: COOLDOWN | E28: 4 | F28: STANDARD | G28: Doorway Hip Flexor Lunge | H28: 2 | I28: 45s each side | J28: RIGHT side priority — desk posture fix | O28: Posterior pelvic tilt throughout stretch
A29: P1-D5-MOB-1-STD | B29: 1 | C29: 5 | D29: MOBILITY | E29: 1 | F29: STANDARD | G29: Cossack Squat | H29: 2 | I29: 6 each side | J29: Load adductors through full range | O29: Slow descent, feel the inner thigh — this IS hip rehab
A30: P1-D5-MOB-2-STD | B30: 1 | C30: 5 | D30: MOBILITY | E30: 2 | F30: STANDARD | G30: Band Hip Abduction Standing | H30: 2 | I30: 15 reps each | J30: Straight leg — glute fires
A31: P1-D5-MOB-3-STD | B31: 1 | C31: 5 | D31: MOBILITY | E31: 3 | F31: STANDARD | G31: Adductor Stretch + Knee Drive | H31: 2 | I31: 45s each | J31: Inner thigh tension then release | O31: Wide stance, shift weight side to side
A32: P1-D5-MOB-4-STD | B32: 1 | C32: 5 | D32: MOBILITY | E32: 4 | F32: STANDARD | G32: Hip Flexion + External Rotation | H32: 2 | I32: 45s each | J32: RIGHT hip focus
A33: P1-D5-MOB-5-STD | B33: 1 | C33: 5 | D33: MOBILITY | E33: 5 | F33: STANDARD | G33: Supine Hip CARs | H33: 2 | I33: 5 each direction | J33: Full controlled circles
A34: P1-D5-MOB-1-HA | B34: 1 | C34: 5 | D34: MOBILITY | E34: 1 | F34: HIGH_ALERT | G34: Hip CARs (Slow — Full ROM) | H34: 2 | I34: 5 each direction | J34: Maximum joint range at zero load | O34: HIGH ALERT: prioritise range over reps today
A35: P1-D5-MOB-2-HA | B35: 1 | C35: 5 | D35: MOBILITY | E35: 2 | F35: HIGH_ALERT | G35: Lying Hip IR + Traction | H35: 2 | I35: 60s each direction | J35: Gentle traction into internal rotation | O35: Towel under knee for support if needed
A36: P1-D5-MOB-3-HA | B36: 1 | C36: 5 | D36: MOBILITY | E36: 3 | F36: HIGH_ALERT | G36: Cat-Cow + Hip Circles | H36: 2 | I36: 8 reps | J36: Lumbar and hip joint warm-up
A37: P1-D5-MOB-4-HA | B37: 1 | C37: 5 | D37: MOBILITY | E37: 4 | F37: HIGH_ALERT | G37: Adductor PAILs-RAILs | H37: 2 | I37: 45s hold each | J37: Contract then relax — neurological reset | O37: 5s contract against floor, then deepen stretch
A38: P1-D5-MOB-5-HA | B38: 1 | C38: 5 | D38: MOBILITY | E38: 5 | F38: HIGH_ALERT | G38: 90/90 Stretch (Both Positions) | H38: 3 | I38: 90s each side | J38: RIGHT side 3 sets — non-negotiable | O38: This is your primary hip rehab movement on HIGH ALERT days
A39: P1-D5-STR-1 | B39: 1 | C39: 5 | D39: STRENGTH | E39: 1 | F39: STANDARD | G39: Bulgarian Split Squat | H39: 4 | I39: 6 reps each leg | J39: Bodyweight to start — add load when form is perfect | K39: Single-Leg Broad Jump | L39: 4 | M39: 3 | O39: RIGHT leg forward first — this exposes the imbalance. Control the descent.
A40: P1-D5-STR-2 | B40: 1 | C40: 5 | D40: STRENGTH | E40: 2 | F40: STANDARD | G40: Single-Leg Romanian Deadlift | H40: 3 | I40: 8 reps each | J40: Controlled — feel hamstring stretch
...

Sheet FightLog
A1: Date | B1: Day | C1: Phase | D1: Hip_Score | E1: Ex1_S1_kg | F1: Ex1_S1_reps | G1: Ex1_S2_kg | H1: Ex1_S2_reps | I1: Ex1_S3_kg | J1: Ex1_S3_reps | K1: Ex1_S4_kg | L1: Ex1_S4_reps | M1: Ex2_S1_kg | N1: Ex2_S1_reps | O1: Ex2_S2_kg | P1: Ex2_S2_reps | Q1: Ex2_S3_kg | R1: Ex2_S3_reps | S1: Ex2_S4_kg | T1: Ex2_S4_reps | U1: Ex3_S1_kg | V1: Ex3_S1_reps | W1: Ex3_S2_kg | X1: Ex3_S2_reps | Y1: Ex3_S3_kg | Z1: Ex3_S3_reps | AA1: Ex3_S4_kg | AB1: Ex3_S4_reps | AC1: Ex4_S1_kg | AD1: Ex4_S1_reps | AE1: Ex4_S2_kg | AF1: Ex4_S2_reps | AG1: Ex4_S3_kg | AH1: Ex4_S3_reps | AI1: Ex4_S4_kg | AJ1: Ex4_S4_reps | AK1: Mob_Done | AL1: Clr_Done | AM1: Bag_Rounds | AN1: Notes | AO1: Completeness_%

Sheet Stats
A1: 📈 PERFORMANCE STATS
A3: TOTAL SESSIONS LOGGED | B3: =COUNTA(FightLog!A:A)-1
A4: CURRENT PHASE | B4: =Settings!B3
A5: PHASE UNLOCK STATUS | B5: =Settings!B10
A7: AVG COMPLETENESS % | B7: =IFERROR(AVERAGE(FightLog!AO:AO),"-")
A8: BEST SESSION % | B8: =IFERROR(MAX(FightLog!AO:AO),"-")
A9: LOWEST HIP SCORE | B9: =IFERROR(MIN(FightLog!D:D),"-")
A10: AVG HIP SCORE | B10: =IFERROR(AVERAGE(FightLog!D:D),"-")
